Traceback (most recent call last):
  File "/root/DNNM/mach5 baseline/run.py", line 261, in <module>
    train()
  File "/root/DNNM/mach5 baseline/run.py", line 162, in train
    train_dataloader, test_dataloader, d_channel = pipeline(batch_size=hp.batch_size, window_size=hp.window_size, pred_size=hp.pred_size)
  File "/root/DNNM/mach5 baseline/run.py", line 98, in pipeline
    train_dataset = Create_Dataset(datafile=path, window_size=window_size, split=hp.split, mode='train', pred_size=pred_size)
  File "/root/DNNM/mach5 baseline/dataset_process/dataset_process.py", line 26, in __init__
    df = pd.read_csv(datafile, delimiter=',', index_col=0)
  File "/root/ml/lib/python3.10/site-packages/pandas/io/parsers/readers.py", line 912, in read_csv
    return _read(filepath_or_buffer, kwds)
  File "/root/ml/lib/python3.10/site-packages/pandas/io/parsers/readers.py", line 577, in _read
    parser = TextFileReader(filepath_or_buffer, **kwds)
  File "/root/ml/lib/python3.10/site-packages/pandas/io/parsers/readers.py", line 1407, in __init__
    self._engine = self._make_engine(f, self.engine)
  File "/root/ml/lib/python3.10/site-packages/pandas/io/parsers/readers.py", line 1661, in _make_engine
    self.handles = get_handle(
  File "/root/ml/lib/python3.10/site-packages/pandas/io/common.py", line 859, in get_handle
    handle = open(
FileNotFoundError: [Errno 2] No such file or directory: '/root/DNNM/mach1/datasets/SPY_30min_test.txt'