Traceback (most recent call last):
  File "/root/ml/lib/python3.10/site-packages/pandas/core/indexes/base.py", line 3652, in get_loc
    return self._engine.get_loc(casted_key)
  File "pandas/_libs/index.pyx", line 147, in pandas._libs.index.IndexEngine.get_loc
  File "pandas/_libs/index.pyx", line 176, in pandas._libs.index.IndexEngine.get_loc
  File "pandas/_libs/hashtable_class_helper.pxi", line 7080, in pandas._libs.hashtable.PyObjectHashTable.get_item
  File "pandas/_libs/hashtable_class_helper.pxi", line 7088, in pandas._libs.hashtable.PyObjectHashTable.get_item
KeyError: 4
The above exception was the direct cause of the following exception:
Traceback (most recent call last):
  File "/root/DNNM/mach5 baseline/run.py", line 261, in <module>
    train()
  File "/root/DNNM/mach5 baseline/run.py", line 162, in train
    train_dataloader, test_dataloader, d_channel = pipeline(batch_size=hp.batch_size, window_size=hp.window_size, pred_size=hp.pred_size)
  File "/root/DNNM/mach5 baseline/run.py", line 98, in pipeline
    train_dataset = Create_Dataset(datafile=path, window_size=window_size, split=hp.split, mode='train', pred_size=pred_size)
  File "/root/DNNM/mach5 baseline/dataset_process/dataset_process.py", line 28, in __init__
    rawtrainingdata = pd.DataFrame(df[4]).to_numpy()
  File "/root/ml/lib/python3.10/site-packages/pandas/core/frame.py", line 3761, in __getitem__
    indexer = self.columns.get_loc(key)
  File "/root/ml/lib/python3.10/site-packages/pandas/core/indexes/base.py", line 3654, in get_loc
    raise KeyError(key) from err
KeyError: 4